GLOB sdist-make: /code/modules/invenio-oaiharvester/setup.py
ERROR: invocation failed (exit code 1), logfile: /code/modules/invenio-oaiharvester/.tox/log/GLOB-0.log
================================== log start ===================================
WARNING: Retrying (Retry(total=4, connect=None, read=None, redirect=None, status=None)) after connection broken by 'ProtocolError('Connection aborted.', ConnectionResetError(104, 'Connection reset by peer'))': /simple/pytest-runner/
WARNING: Retrying (Retry(total=3, connect=None, read=None, redirect=None, status=None)) after connection broken by 'ProtocolError('Connection aborted.', ConnectionResetError(104, 'Connection reset by peer'))': /simple/pytest-runner/
WARNING: Retrying (Retry(total=2, connect=None, read=None, redirect=None, status=None)) after connection broken by 'ProtocolError('Connection aborted.', ConnectionResetError(104, 'Connection reset by peer'))': /simple/pytest-runner/
WARNING: Retrying (Retry(total=1, connect=None, read=None, redirect=None, status=None)) after connection broken by 'ProtocolError('Connection aborted.', ConnectionResetError(104, 'Connection reset by peer'))': /simple/pytest-runner/
WARNING: Retrying (Retry(total=0, connect=None, read=None, redirect=None, status=None)) after connection broken by 'ProtocolError('Connection aborted.', ConnectionResetError(104, 'Connection reset by peer'))': /simple/pytest-runner/
ERROR: Could not find a version that satisfies the requirement pytest-runner<5,>=3.0.0 (from versions: none)
ERROR: No matching distribution found for pytest-runner<5,>=3.0.0
/home/invenio/.virtualenvs/invenio/lib/python3.6/site-packages/setuptools/installer.py:30: SetuptoolsDeprecationWarning: setuptools.installer is deprecated. Requirements should be satisfied by a PEP 517 installer.
  SetuptoolsDeprecationWarning,
Traceback (most recent call last):
  File "/home/invenio/.virtualenvs/invenio/lib/python3.6/site-packages/setuptools/installer.py", line 82, in fetch_build_egg
    subprocess.check_call(cmd)
  File "/usr/local/lib/python3.6/subprocess.py", line 311, in check_call
    raise CalledProcessError(retcode, cmd)
subprocess.CalledProcessError: Command '['/home/invenio/.virtualenvs/invenio/bin/python', '-m', 'pip', '--disable-pip-version-check', 'wheel', '--no-deps', '-w', '/var/tmp/tmpe1meaej9', '--quiet', 'pytest-runner<5,>=3.0.0']' returned non-zero exit status 1.

The above exception was the direct cause of the following exception:

Traceback (most recent call last):
  File "setup.py", line 140, in <module>
    'Development Status :: 1 - Planning',
  File "/home/invenio/.virtualenvs/invenio/lib/python3.6/site-packages/setuptools/__init__.py", line 152, in setup
    _install_setup_requires(attrs)
  File "/home/invenio/.virtualenvs/invenio/lib/python3.6/site-packages/setuptools/__init__.py", line 147, in _install_setup_requires
    dist.fetch_build_eggs(dist.setup_requires)
  File "/home/invenio/.virtualenvs/invenio/lib/python3.6/site-packages/setuptools/dist.py", line 815, in fetch_build_eggs
    replace_conflicting=True,
  File "/home/invenio/.virtualenvs/invenio/lib/python3.6/site-packages/pkg_resources/__init__.py", line 773, in resolve
    replace_conflicting=replace_conflicting
  File "/home/invenio/.virtualenvs/invenio/lib/python3.6/site-packages/pkg_resources/__init__.py", line 1056, in best_match
    return self.obtain(req, installer)
  File "/home/invenio/.virtualenvs/invenio/lib/python3.6/site-packages/pkg_resources/__init__.py", line 1068, in obtain
    return installer(requirement)
  File "/home/invenio/.virtualenvs/invenio/lib/python3.6/site-packages/setuptools/dist.py", line 883, in fetch_build_egg
    return fetch_build_egg(self, req)
  File "/home/invenio/.virtualenvs/invenio/lib/python3.6/site-packages/setuptools/installer.py", line 84, in fetch_build_egg
    raise DistutilsError(str(e)) from e
distutils.errors.DistutilsError: Command '['/home/invenio/.virtualenvs/invenio/bin/python', '-m', 'pip', '--disable-pip-version-check', 'wheel', '--no-deps', '-w', '/var/tmp/tmpe1meaej9', '--quiet', 'pytest-runner<5,>=3.0.0']' returned non-zero exit status 1.

=================================== log end ====================================
ERROR: FAIL could not package project - v = InvocationError('/home/invenio/.virtualenvs/invenio/bin/python setup.py sdist --formats=zip --dist-dir .tox/dist', 1)
